[2024-03-09T17:31:13.581+0000] {taskinstance.py:1979} INFO - Dependencies all met for dep_context=non-requeueable deps ti=<TaskInstance: ETL_Flow.fact_stg2dwh scheduled__2024-03-05T06:00:00+00:00 [queued]>
[2024-03-09T17:31:13.644+0000] {taskinstance.py:1979} INFO - Dependencies all met for dep_context=requeueable deps ti=<TaskInstance: ETL_Flow.fact_stg2dwh scheduled__2024-03-05T06:00:00+00:00 [queued]>
[2024-03-09T17:31:13.648+0000] {taskinstance.py:2193} INFO - Starting attempt 1 of 6
[2024-03-09T17:31:13.766+0000] {taskinstance.py:2214} INFO - Executing <Task(PostgresOperator): fact_stg2dwh> on 2024-03-05 06:00:00+00:00
[2024-03-09T17:31:13.784+0000] {standard_task_runner.py:60} INFO - Started process 3450 to run task
[2024-03-09T17:31:13.841+0000] {standard_task_runner.py:87} INFO - Running: ['***', 'tasks', 'run', 'ETL_Flow', 'fact_stg2dwh', 'scheduled__2024-03-05T06:00:00+00:00', '--job-id', '307', '--raw', '--subdir', 'DAGS_FOLDER/etl2.py', '--cfg-path', '/tmp/tmpryioplb6']
[2024-03-09T17:31:13.848+0000] {standard_task_runner.py:88} INFO - Job 307: Subtask fact_stg2dwh
[2024-03-09T17:31:14.167+0000] {task_command.py:423} INFO - Running <TaskInstance: ETL_Flow.fact_stg2dwh scheduled__2024-03-05T06:00:00+00:00 [running]> on host 3b9d9f11e4f2
[2024-03-09T17:31:14.685+0000] {taskinstance.py:2510} INFO - Exporting env vars: AIRFLOW_CTX_DAG_OWNER='coder2j' AIRFLOW_CTX_DAG_ID='ETL_Flow' AIRFLOW_CTX_TASK_ID='fact_stg2dwh' AIRFLOW_CTX_EXECUTION_DATE='2024-03-05T06:00:00+00:00' AIRFLOW_CTX_TRY_NUMBER='1' AIRFLOW_CTX_DAG_RUN_ID='scheduled__2024-03-05T06:00:00+00:00'
[2024-03-09T17:31:14.691+0000] {sql.py:276} INFO - Executing: insert into DWH_Fact_Product_In_Order
select * from
STG_Fact_Product_In_Order;
[2024-03-09T17:31:14.750+0000] {base.py:83} INFO - Using connection ID 'postgres_localhost' for task execution.
[2024-03-09T17:31:14.854+0000] {base.py:83} INFO - Using connection ID 'postgres_localhost' for task execution.
[2024-03-09T17:31:14.965+0000] {sql.py:457} INFO - Running statement: insert into DWH_Fact_Product_In_Order
select * from
STG_Fact_Product_In_Order;, parameters: None
[2024-03-09T17:31:15.013+0000] {taskinstance.py:2728} ERROR - Task failed with exception
Traceback (most recent call last):
  File "/home/airflow/.local/lib/python3.8/site-packages/airflow/models/taskinstance.py", line 444, in _execute_task
    result = _execute_callable(context=context, **execute_callable_kwargs)
  File "/home/airflow/.local/lib/python3.8/site-packages/airflow/models/taskinstance.py", line 414, in _execute_callable
    return execute_callable(context=context, **execute_callable_kwargs)
  File "/home/airflow/.local/lib/python3.8/site-packages/airflow/providers/common/sql/operators/sql.py", line 282, in execute
    output = hook.run(
  File "/home/airflow/.local/lib/python3.8/site-packages/airflow/providers/common/sql/hooks/sql.py", line 404, in run
    self._run_command(cur, sql_statement, parameters)
  File "/home/airflow/.local/lib/python3.8/site-packages/airflow/providers/common/sql/hooks/sql.py", line 462, in _run_command
    cur.execute(sql_statement)
psycopg2.errors.UndefinedTable: relation "dwh_fact_product_in_order" does not exist
LINE 1: insert into DWH_Fact_Product_In_Order
                    ^

[2024-03-09T17:31:15.078+0000] {taskinstance.py:1149} INFO - Marking task as UP_FOR_RETRY. dag_id=ETL_Flow, task_id=fact_stg2dwh, execution_date=20240305T060000, start_date=20240309T173113, end_date=20240309T173115
[2024-03-09T17:31:15.139+0000] {standard_task_runner.py:107} ERROR - Failed to execute job 307 for task fact_stg2dwh (relation "dwh_fact_product_in_order" does not exist
LINE 1: insert into DWH_Fact_Product_In_Order
                    ^
; 3450)
[2024-03-09T17:31:15.172+0000] {local_task_job_runner.py:234} INFO - Task exited with return code 1
[2024-03-09T17:31:18.323+0000] {taskinstance.py:3309} INFO - 0 downstream tasks scheduled from follow-on schedule check
