[2024-03-20T16:08:05.544+0000] {taskinstance.py:1979} INFO - Dependencies all met for dep_context=non-requeueable deps ti=<TaskInstance: ETL_Flow.insert_data_from_files manual__2024-03-20T16:07:57.433347+00:00 [queued]>
[2024-03-20T16:08:05.568+0000] {taskinstance.py:1979} INFO - Dependencies all met for dep_context=requeueable deps ti=<TaskInstance: ETL_Flow.insert_data_from_files manual__2024-03-20T16:07:57.433347+00:00 [queued]>
[2024-03-20T16:08:05.570+0000] {taskinstance.py:2193} INFO - Starting attempt 1 of 6
[2024-03-20T16:08:05.609+0000] {taskinstance.py:2214} INFO - Executing <Task(PythonOperator): insert_data_from_files> on 2024-03-20 16:07:57.433347+00:00
[2024-03-20T16:08:05.625+0000] {standard_task_runner.py:60} INFO - Started process 3534 to run task
[2024-03-20T16:08:05.633+0000] {standard_task_runner.py:87} INFO - Running: ['***', 'tasks', 'run', 'ETL_Flow', 'insert_data_from_files', 'manual__2024-03-20T16:07:57.433347+00:00', '--job-id', '2033', '--raw', '--subdir', 'DAGS_FOLDER/etl2.py', '--cfg-path', '/tmp/tmpxyi_khgh']
[2024-03-20T16:08:05.639+0000] {standard_task_runner.py:88} INFO - Job 2033: Subtask insert_data_from_files
[2024-03-20T16:08:05.771+0000] {task_command.py:423} INFO - Running <TaskInstance: ETL_Flow.insert_data_from_files manual__2024-03-20T16:07:57.433347+00:00 [running]> on host a1a2ab3031a9
[2024-03-20T16:08:06.339+0000] {taskinstance.py:2510} INFO - Exporting env vars: AIRFLOW_CTX_DAG_OWNER='coder2j' AIRFLOW_CTX_DAG_ID='ETL_Flow' AIRFLOW_CTX_TASK_ID='insert_data_from_files' AIRFLOW_CTX_EXECUTION_DATE='2024-03-20T16:07:57.433347+00:00' AIRFLOW_CTX_TRY_NUMBER='1' AIRFLOW_CTX_DAG_RUN_ID='manual__2024-03-20T16:07:57.433347+00:00'
[2024-03-20T16:08:06.344+0000] {taskinstance.py:2728} ERROR - Task failed with exception
Traceback (most recent call last):
  File "/home/airflow/.local/lib/python3.8/site-packages/airflow/models/taskinstance.py", line 444, in _execute_task
    result = _execute_callable(context=context, **execute_callable_kwargs)
  File "/home/airflow/.local/lib/python3.8/site-packages/airflow/models/taskinstance.py", line 414, in _execute_callable
    return execute_callable(context=context, **execute_callable_kwargs)
  File "/home/airflow/.local/lib/python3.8/site-packages/airflow/operators/python.py", line 200, in execute
    return_value = self.execute_callable()
  File "/home/airflow/.local/lib/python3.8/site-packages/airflow/operators/python.py", line 217, in execute_callable
    return self.python_callable(*self.op_args, **self.op_kwargs)
TypeError: insert_data_from_files() missing 2 required positional arguments: 'file_paths' and 'table_names'
[2024-03-20T16:08:06.401+0000] {taskinstance.py:1149} INFO - Marking task as UP_FOR_RETRY. dag_id=ETL_Flow, task_id=insert_data_from_files, execution_date=20240320T160757, start_date=20240320T160805, end_date=20240320T160806
[2024-03-20T16:08:06.479+0000] {standard_task_runner.py:107} ERROR - Failed to execute job 2033 for task insert_data_from_files (insert_data_from_files() missing 2 required positional arguments: 'file_paths' and 'table_names'; 3534)
[2024-03-20T16:08:06.573+0000] {local_task_job_runner.py:234} INFO - Task exited with return code 1
[2024-03-20T16:08:06.688+0000] {taskinstance.py:3309} INFO - 0 downstream tasks scheduled from follow-on schedule check
