[2024-03-12T18:26:10.757+0000] {taskinstance.py:1979} INFO - Dependencies all met for dep_context=non-requeueable deps ti=<TaskInstance: ETL_Flow.referential_integrity manual__2024-03-12T18:09:34.801045+00:00 [queued]>
[2024-03-12T18:26:10.785+0000] {taskinstance.py:1979} INFO - Dependencies all met for dep_context=requeueable deps ti=<TaskInstance: ETL_Flow.referential_integrity manual__2024-03-12T18:09:34.801045+00:00 [queued]>
[2024-03-12T18:26:10.786+0000] {taskinstance.py:2193} INFO - Starting attempt 3 of 6
[2024-03-12T18:26:10.834+0000] {taskinstance.py:2214} INFO - Executing <Task(PostgresOperator): referential_integrity> on 2024-03-12 18:09:34.801045+00:00
[2024-03-12T18:26:10.847+0000] {standard_task_runner.py:60} INFO - Started process 283 to run task
[2024-03-12T18:26:10.860+0000] {standard_task_runner.py:87} INFO - Running: ['***', 'tasks', 'run', 'ETL_Flow', 'referential_integrity', 'manual__2024-03-12T18:09:34.801045+00:00', '--job-id', '1020', '--raw', '--subdir', 'DAGS_FOLDER/etl2.py', '--cfg-path', '/tmp/tmpv6nqd695']
[2024-03-12T18:26:10.872+0000] {standard_task_runner.py:88} INFO - Job 1020: Subtask referential_integrity
[2024-03-12T18:26:11.254+0000] {task_command.py:423} INFO - Running <TaskInstance: ETL_Flow.referential_integrity manual__2024-03-12T18:09:34.801045+00:00 [running]> on host f325c35ec09e
[2024-03-12T18:26:13.160+0000] {taskinstance.py:2510} INFO - Exporting env vars: AIRFLOW_CTX_DAG_OWNER='coder2j' AIRFLOW_CTX_DAG_ID='ETL_Flow' AIRFLOW_CTX_TASK_ID='referential_integrity' AIRFLOW_CTX_EXECUTION_DATE='2024-03-12T18:09:34.801045+00:00' AIRFLOW_CTX_TRY_NUMBER='3' AIRFLOW_CTX_DAG_RUN_ID='manual__2024-03-12T18:09:34.801045+00:00'
[2024-03-12T18:26:13.164+0000] {sql.py:276} INFO - Executing: update STG_Fact_Product_In_Order
set Product_ID='unknown'
where Product_ID not in (
                            select distinct Product_ID 
                            from DWH_Dim_Products
                        );

update STG_Dim_Employees
set Employee_ID='unknown'
where Employee_ID not in (
                            select distinct Employee_ID 
                            from DWH_Dim_Employees
                        );

update STG_Dim_Customers
set Customer_ID='unknown'
where Customer_ID not in (
                            select distinct Customer_ID 
                            from DWH_Dim_Customers
                        );

[2024-03-12T18:26:13.181+0000] {base.py:83} INFO - Using connection ID 'postgres_localhost' for task execution.
[2024-03-12T18:26:13.196+0000] {base.py:83} INFO - Using connection ID 'postgres_localhost' for task execution.
[2024-03-12T18:26:13.221+0000] {sql.py:457} INFO - Running statement: update STG_Fact_Product_In_Order
set Product_ID='unknown'
where Product_ID not in (
                            select distinct Product_ID 
                            from DWH_Dim_Products
                        );

update STG_Dim_Employees
set Employee_ID='unknown'
where Employee_ID not in (
                            select distinct Employee_ID 
                            from DWH_Dim_Employees
                        );

update STG_Dim_Customers
set Customer_ID='unknown'
where Customer_ID not in (
                            select distinct Customer_ID 
                            from DWH_Dim_Customers
                        );
, parameters: None
[2024-03-12T18:26:13.230+0000] {taskinstance.py:2728} ERROR - Task failed with exception
Traceback (most recent call last):
  File "/home/airflow/.local/lib/python3.8/site-packages/airflow/models/taskinstance.py", line 444, in _execute_task
    result = _execute_callable(context=context, **execute_callable_kwargs)
  File "/home/airflow/.local/lib/python3.8/site-packages/airflow/models/taskinstance.py", line 414, in _execute_callable
    return execute_callable(context=context, **execute_callable_kwargs)
  File "/home/airflow/.local/lib/python3.8/site-packages/airflow/providers/common/sql/operators/sql.py", line 282, in execute
    output = hook.run(
  File "/home/airflow/.local/lib/python3.8/site-packages/airflow/providers/common/sql/hooks/sql.py", line 404, in run
    self._run_command(cur, sql_statement, parameters)
  File "/home/airflow/.local/lib/python3.8/site-packages/airflow/providers/common/sql/hooks/sql.py", line 462, in _run_command
    cur.execute(sql_statement)
psycopg2.errors.UndefinedTable: relation "stg_fact_product_in_order" does not exist
LINE 1: update STG_Fact_Product_In_Order
               ^

[2024-03-12T18:26:13.255+0000] {taskinstance.py:1149} INFO - Marking task as UP_FOR_RETRY. dag_id=ETL_Flow, task_id=referential_integrity, execution_date=20240312T180934, start_date=20240312T182610, end_date=20240312T182613
[2024-03-12T18:26:13.299+0000] {standard_task_runner.py:107} ERROR - Failed to execute job 1020 for task referential_integrity (relation "stg_fact_product_in_order" does not exist
LINE 1: update STG_Fact_Product_In_Order
               ^
; 283)
[2024-03-12T18:26:13.343+0000] {local_task_job_runner.py:234} INFO - Task exited with return code 1
[2024-03-12T18:26:13.370+0000] {taskinstance.py:3309} INFO - 0 downstream tasks scheduled from follow-on schedule check
