[2024-03-12T17:31:37.742+0000] {scheduler_job_runner.py:781} ERROR - Executor reports task instance <TaskInstance: ETL_Flow.dwh_backup scheduled__2024-02-29T06:00:00+00:00 [queued]> finished (success) although the task says it's queued. (Info: None) Was the task killed externally?
