[2024-03-12T17:33:38.360+0000] {scheduler_job_runner.py:1575} WARNING - Marking task instance <TaskInstance: ETL_Flow.dim_mrr2stg scheduled__2024-03-03T06:00:00+00:00 [queued]> stuck in queued as failed. If the task instance has available retries, it will be retried.
[2024-03-12T17:33:41.084+0000] {scheduler_job_runner.py:781} ERROR - Executor reports task instance <TaskInstance: ETL_Flow.dim_mrr2stg scheduled__2024-03-03T06:00:00+00:00 [queued]> finished (failed) although the task says it's queued. (Info: None) Was the task killed externally?
