[2024-03-12T17:49:28.105+0000] {taskinstance.py:1979} INFO - Dependencies all met for dep_context=non-requeueable deps ti=<TaskInstance: ETL_Flow.dim_mrr2stg scheduled__2024-03-03T06:00:00+00:00 [queued]>
[2024-03-12T17:49:28.388+0000] {taskinstance.py:1979} INFO - Dependencies all met for dep_context=requeueable deps ti=<TaskInstance: ETL_Flow.dim_mrr2stg scheduled__2024-03-03T06:00:00+00:00 [queued]>
[2024-03-12T17:49:28.409+0000] {taskinstance.py:2193} INFO - Starting attempt 5 of 6
[2024-03-12T17:49:29.118+0000] {taskinstance.py:2214} INFO - Executing <Task(PostgresOperator): dim_mrr2stg> on 2024-03-03 06:00:00+00:00
[2024-03-12T17:49:29.135+0000] {standard_task_runner.py:60} INFO - Started process 1296 to run task
[2024-03-12T17:49:29.176+0000] {standard_task_runner.py:87} INFO - Running: ['***', 'tasks', 'run', 'ETL_Flow', 'dim_mrr2stg', 'scheduled__2024-03-03T06:00:00+00:00', '--job-id', '833', '--raw', '--subdir', 'DAGS_FOLDER/etl2.py', '--cfg-path', '/tmp/tmp713hcx5j']
[2024-03-12T17:49:29.223+0000] {standard_task_runner.py:88} INFO - Job 833: Subtask dim_mrr2stg
[2024-03-12T17:49:29.891+0000] {task_command.py:423} INFO - Running <TaskInstance: ETL_Flow.dim_mrr2stg scheduled__2024-03-03T06:00:00+00:00 [running]> on host e2878ba2ad26
[2024-03-12T17:49:50.751+0000] {job.py:213} ERROR - Job heartbeat got an exception
Traceback (most recent call last):
  File "/home/airflow/.local/lib/python3.8/site-packages/sqlalchemy/engine/base.py", line 3371, in _wrap_pool_connect
    return fn()
  File "/home/airflow/.local/lib/python3.8/site-packages/sqlalchemy/pool/base.py", line 327, in connect
    return _ConnectionFairy._checkout(self)
  File "/home/airflow/.local/lib/python3.8/site-packages/sqlalchemy/pool/base.py", line 894, in _checkout
    fairy = _ConnectionRecord.checkout(pool)
  File "/home/airflow/.local/lib/python3.8/site-packages/sqlalchemy/pool/base.py", line 493, in checkout
    rec = pool._do_get()
  File "/home/airflow/.local/lib/python3.8/site-packages/sqlalchemy/pool/impl.py", line 256, in _do_get
    return self._create_connection()
  File "/home/airflow/.local/lib/python3.8/site-packages/sqlalchemy/pool/base.py", line 273, in _create_connection
    return _ConnectionRecord(self)
  File "/home/airflow/.local/lib/python3.8/site-packages/sqlalchemy/pool/base.py", line 388, in __init__
    self.__connect()
  File "/home/airflow/.local/lib/python3.8/site-packages/sqlalchemy/pool/base.py", line 691, in __connect
    pool.logger.debug("Error on connect(): %s", e)
  File "/home/airflow/.local/lib/python3.8/site-packages/sqlalchemy/util/langhelpers.py", line 70, in __exit__
    compat.raise_(
  File "/home/airflow/.local/lib/python3.8/site-packages/sqlalchemy/util/compat.py", line 211, in raise_
    raise exception
  File "/home/airflow/.local/lib/python3.8/site-packages/sqlalchemy/pool/base.py", line 686, in __connect
    self.dbapi_connection = connection = pool._invoke_creator(self)
  File "/home/airflow/.local/lib/python3.8/site-packages/sqlalchemy/engine/create.py", line 574, in connect
    return dialect.connect(*cargs, **cparams)
  File "/home/airflow/.local/lib/python3.8/site-packages/sqlalchemy/engine/default.py", line 598, in connect
    return self.dbapi.connect(*cargs, **cparams)
  File "/home/airflow/.local/lib/python3.8/site-packages/psycopg2/__init__.py", line 122, in connect
    conn = _connect(dsn, connection_factory=connection_factory, **kwasync)
psycopg2.OperationalError: could not translate host name "postgres" to address: Temporary failure in name resolution


The above exception was the direct cause of the following exception:

Traceback (most recent call last):
  File "/home/airflow/.local/lib/python3.8/site-packages/airflow/jobs/job.py", line 187, in heartbeat
    self._merge_from(Job._fetch_from_db(self, session))
  File "/home/airflow/.local/lib/python3.8/site-packages/airflow/api_internal/internal_api_call.py", line 114, in wrapper
    return func(*args, **kwargs)
  File "/home/airflow/.local/lib/python3.8/site-packages/airflow/utils/session.py", line 76, in wrapper
    return func(*args, **kwargs)
  File "/home/airflow/.local/lib/python3.8/site-packages/airflow/jobs/job.py", line 308, in _fetch_from_db
    session.merge(job)
  File "/home/airflow/.local/lib/python3.8/site-packages/sqlalchemy/orm/session.py", line 3056, in merge
    return self._merge(
  File "/home/airflow/.local/lib/python3.8/site-packages/sqlalchemy/orm/session.py", line 3136, in _merge
    merged = self.get(
  File "/home/airflow/.local/lib/python3.8/site-packages/sqlalchemy/orm/session.py", line 2853, in get
    return self._get_impl(
  File "/home/airflow/.local/lib/python3.8/site-packages/sqlalchemy/orm/session.py", line 2975, in _get_impl
    return db_load_fn(
  File "/home/airflow/.local/lib/python3.8/site-packages/sqlalchemy/orm/loading.py", line 530, in load_on_pk_identity
    session.execute(
  File "/home/airflow/.local/lib/python3.8/site-packages/sqlalchemy/orm/session.py", line 1716, in execute
    conn = self._connection_for_bind(bind)
  File "/home/airflow/.local/lib/python3.8/site-packages/sqlalchemy/orm/session.py", line 1555, in _connection_for_bind
    return self._transaction._connection_for_bind(
  File "/home/airflow/.local/lib/python3.8/site-packages/sqlalchemy/orm/session.py", line 750, in _connection_for_bind
    conn = bind.connect()
  File "/home/airflow/.local/lib/python3.8/site-packages/sqlalchemy/future/engine.py", line 412, in connect
    return super(Engine, self).connect()
  File "/home/airflow/.local/lib/python3.8/site-packages/sqlalchemy/engine/base.py", line 3325, in connect
    return self._connection_cls(self, close_with_result=close_with_result)
  File "/home/airflow/.local/lib/python3.8/site-packages/sqlalchemy/engine/base.py", line 96, in __init__
    else engine.raw_connection()
  File "/home/airflow/.local/lib/python3.8/site-packages/sqlalchemy/engine/base.py", line 3404, in raw_connection
    return self._wrap_pool_connect(self.pool.connect, _connection)
  File "/home/airflow/.local/lib/python3.8/site-packages/sqlalchemy/engine/base.py", line 3374, in _wrap_pool_connect
    Connection._handle_dbapi_exception_noconnection(
  File "/home/airflow/.local/lib/python3.8/site-packages/sqlalchemy/engine/base.py", line 2208, in _handle_dbapi_exception_noconnection
    util.raise_(
  File "/home/airflow/.local/lib/python3.8/site-packages/sqlalchemy/util/compat.py", line 211, in raise_
    raise exception
  File "/home/airflow/.local/lib/python3.8/site-packages/sqlalchemy/engine/base.py", line 3371, in _wrap_pool_connect
    return fn()
  File "/home/airflow/.local/lib/python3.8/site-packages/sqlalchemy/pool/base.py", line 327, in connect
    return _ConnectionFairy._checkout(self)
  File "/home/airflow/.local/lib/python3.8/site-packages/sqlalchemy/pool/base.py", line 894, in _checkout
    fairy = _ConnectionRecord.checkout(pool)
  File "/home/airflow/.local/lib/python3.8/site-packages/sqlalchemy/pool/base.py", line 493, in checkout
    rec = pool._do_get()
  File "/home/airflow/.local/lib/python3.8/site-packages/sqlalchemy/pool/impl.py", line 256, in _do_get
    return self._create_connection()
  File "/home/airflow/.local/lib/python3.8/site-packages/sqlalchemy/pool/base.py", line 273, in _create_connection
    return _ConnectionRecord(self)
  File "/home/airflow/.local/lib/python3.8/site-packages/sqlalchemy/pool/base.py", line 388, in __init__
    self.__connect()
  File "/home/airflow/.local/lib/python3.8/site-packages/sqlalchemy/pool/base.py", line 691, in __connect
    pool.logger.debug("Error on connect(): %s", e)
  File "/home/airflow/.local/lib/python3.8/site-packages/sqlalchemy/util/langhelpers.py", line 70, in __exit__
    compat.raise_(
  File "/home/airflow/.local/lib/python3.8/site-packages/sqlalchemy/util/compat.py", line 211, in raise_
    raise exception
  File "/home/airflow/.local/lib/python3.8/site-packages/sqlalchemy/pool/base.py", line 686, in __connect
    self.dbapi_connection = connection = pool._invoke_creator(self)
  File "/home/airflow/.local/lib/python3.8/site-packages/sqlalchemy/engine/create.py", line 574, in connect
    return dialect.connect(*cargs, **cparams)
  File "/home/airflow/.local/lib/python3.8/site-packages/sqlalchemy/engine/default.py", line 598, in connect
    return self.dbapi.connect(*cargs, **cparams)
  File "/home/airflow/.local/lib/python3.8/site-packages/psycopg2/__init__.py", line 122, in connect
    conn = _connect(dsn, connection_factory=connection_factory, **kwasync)
sqlalchemy.exc.OperationalError: (psycopg2.OperationalError) could not translate host name "postgres" to address: Temporary failure in name resolution

(Background on this error at: https://sqlalche.me/e/14/e3q8)
[2024-03-12T17:49:50.973+0000] {job.py:221} ERROR - Job heartbeat failed with error. Scheduler is in unhealthy state
[2024-03-12T17:49:55.843+0000] {taskinstance.py:2510} INFO - Exporting env vars: AIRFLOW_CTX_DAG_OWNER='coder2j' AIRFLOW_CTX_DAG_ID='ETL_Flow' AIRFLOW_CTX_TASK_ID='dim_mrr2stg' AIRFLOW_CTX_EXECUTION_DATE='2024-03-03T06:00:00+00:00' AIRFLOW_CTX_TRY_NUMBER='5' AIRFLOW_CTX_DAG_RUN_ID='scheduled__2024-03-03T06:00:00+00:00'
[2024-03-12T17:49:55.872+0000] {sql.py:276} INFO - Executing: insert into STG_Dim_Products(Product_ID,Product_Name,Supplier,Category,Unit_Price,Unit_Cost)
select 
case when Product_ID similar to '[0-9]+' and cast(Product_ID as int)>=0
then cast(Product_ID as int) else 0 end,
Product_Name,
case when Supplier similar to '[0-9]+' and cast(Supplier as int)>=0
then cast(Supplier as int) else 0 end,
case when Category similar to '[0-9]+' and cast(Category as int)>=0
then cast(Category as int) else 0 end,
case when Unit_Price is null then 0 else cast(Unit_Price as money) end,
case when Unit_Cost is null then 0 else cast(Unit_Cost as money) end
from MRR_Dim_Products;





insert into STG_Dim_Customers(Customer_ID,Company_Name,Contact_Name,Street,City,Postal_Code,Country,Phone,Fax)
select
case when Customer_ID similar to '[0-9]+' and cast(Customer_ID as int)>=0 then cast(Customer_ID as int) else 0 end,
Company_Name,
Contact_Name,
Street,
City,
Postal_Code,
Country,
Phone,
Fax
from MRR_Dim_Customers;


insert into STG_Dim_Employees(Employee_ID,Last_Name,First_Name,Title,Hire_Date,Office,Reports_To,Month_Salary)
select 
case when Employee_ID similar to '[0-9]+' and cast(Employee_ID as int)>=0 then cast(Employee_ID as int) else 0 end,
Last_Name,
First_Name,
Title,
Hire_Date,
case when Office similar to '[0-9]+' and cast(Office as int)>=0 then cast(Office as int) else 0 end,
case when Reports_To similar to '[0-9]+' and cast(Reports_To as int)>=0 then cast(Reports_To as int) else 0 end,
case when Month_Salary is null then 0 else cast(Month_Salary as money) end
from MRR_Dim_Employees;





insert into STG_Dim_Dates(Date,Year,Quarter,Month,Day)
select
d::date,
extract(year from d),
extract(quarter from d),
extract(month from d),
extract(day from d)
from generate_series('2021-01-01'::date, CURRENT_DATE::date, '1 day');

insert into STG_Dim_Time(DateTime,Date,Hour)
select
datetime,
date(DateTime),
extract(hour from DateTime) 
from generate_series('2021-01-01'::date, CURRENT_DATE::date, '1 day');


 
[2024-03-12T17:49:56.521+0000] {base.py:83} INFO - Using connection ID 'postgres_localhost' for task execution.
[2024-03-12T17:49:56.697+0000] {base.py:83} INFO - Using connection ID 'postgres_localhost' for task execution.
[2024-03-12T17:49:57.344+0000] {sql.py:457} INFO - Running statement: insert into STG_Dim_Products(Product_ID,Product_Name,Supplier,Category,Unit_Price,Unit_Cost)
select 
case when Product_ID similar to '[0-9]+' and cast(Product_ID as int)>=0
then cast(Product_ID as int) else 0 end,
Product_Name,
case when Supplier similar to '[0-9]+' and cast(Supplier as int)>=0
then cast(Supplier as int) else 0 end,
case when Category similar to '[0-9]+' and cast(Category as int)>=0
then cast(Category as int) else 0 end,
case when Unit_Price is null then 0 else cast(Unit_Price as money) end,
case when Unit_Cost is null then 0 else cast(Unit_Cost as money) end
from MRR_Dim_Products;





insert into STG_Dim_Customers(Customer_ID,Company_Name,Contact_Name,Street,City,Postal_Code,Country,Phone,Fax)
select
case when Customer_ID similar to '[0-9]+' and cast(Customer_ID as int)>=0 then cast(Customer_ID as int) else 0 end,
Company_Name,
Contact_Name,
Street,
City,
Postal_Code,
Country,
Phone,
Fax
from MRR_Dim_Customers;


insert into STG_Dim_Employees(Employee_ID,Last_Name,First_Name,Title,Hire_Date,Office,Reports_To,Month_Salary)
select 
case when Employee_ID similar to '[0-9]+' and cast(Employee_ID as int)>=0 then cast(Employee_ID as int) else 0 end,
Last_Name,
First_Name,
Title,
Hire_Date,
case when Office similar to '[0-9]+' and cast(Office as int)>=0 then cast(Office as int) else 0 end,
case when Reports_To similar to '[0-9]+' and cast(Reports_To as int)>=0 then cast(Reports_To as int) else 0 end,
case when Month_Salary is null then 0 else cast(Month_Salary as money) end
from MRR_Dim_Employees;





insert into STG_Dim_Dates(Date,Year,Quarter,Month,Day)
select
d::date,
extract(year from d),
extract(quarter from d),
extract(month from d),
extract(day from d)
from generate_series('2021-01-01'::date, CURRENT_DATE::date, '1 day');

insert into STG_Dim_Time(DateTime,Date,Hour)
select
datetime,
date(DateTime),
extract(hour from DateTime) 
from generate_series('2021-01-01'::date, CURRENT_DATE::date, '1 day');


 , parameters: None
[2024-03-12T17:49:57.417+0000] {taskinstance.py:2728} ERROR - Task failed with exception
Traceback (most recent call last):
  File "/home/airflow/.local/lib/python3.8/site-packages/airflow/models/taskinstance.py", line 444, in _execute_task
    result = _execute_callable(context=context, **execute_callable_kwargs)
  File "/home/airflow/.local/lib/python3.8/site-packages/airflow/models/taskinstance.py", line 414, in _execute_callable
    return execute_callable(context=context, **execute_callable_kwargs)
  File "/home/airflow/.local/lib/python3.8/site-packages/airflow/providers/common/sql/operators/sql.py", line 282, in execute
    output = hook.run(
  File "/home/airflow/.local/lib/python3.8/site-packages/airflow/providers/common/sql/hooks/sql.py", line 404, in run
    self._run_command(cur, sql_statement, parameters)
  File "/home/airflow/.local/lib/python3.8/site-packages/airflow/providers/common/sql/hooks/sql.py", line 462, in _run_command
    cur.execute(sql_statement)
psycopg2.errors.UndefinedTable: relation "stg_dim_products" does not exist
LINE 1: insert into STG_Dim_Products(Product_ID,Product_Name,Supplie...
                    ^

[2024-03-12T17:49:57.639+0000] {taskinstance.py:1149} INFO - Marking task as UP_FOR_RETRY. dag_id=ETL_Flow, task_id=dim_mrr2stg, execution_date=20240303T060000, start_date=20240312T174928, end_date=20240312T174957
[2024-03-12T17:49:58.454+0000] {standard_task_runner.py:107} ERROR - Failed to execute job 833 for task dim_mrr2stg (relation "stg_dim_products" does not exist
LINE 1: insert into STG_Dim_Products(Product_ID,Product_Name,Supplie...
                    ^
; 1296)
[2024-03-12T17:49:58.594+0000] {local_task_job_runner.py:234} INFO - Task exited with return code 1
[2024-03-12T17:49:59.535+0000] {taskinstance.py:3309} INFO - 0 downstream tasks scheduled from follow-on schedule check
