[2024-03-12T17:33:18.038+0000] {taskinstance.py:1979} INFO - Dependencies all met for dep_context=non-requeueable deps ti=<TaskInstance: ETL_Flow.fact_stg2dwh manual__2024-03-09T17:34:32.667010+00:00 [queued]>
[2024-03-12T17:33:18.113+0000] {taskinstance.py:1979} INFO - Dependencies all met for dep_context=requeueable deps ti=<TaskInstance: ETL_Flow.fact_stg2dwh manual__2024-03-09T17:34:32.667010+00:00 [queued]>
[2024-03-12T17:33:18.114+0000] {taskinstance.py:2193} INFO - Starting attempt 2 of 6
[2024-03-12T17:33:18.239+0000] {taskinstance.py:2214} INFO - Executing <Task(PostgresOperator): fact_stg2dwh> on 2024-03-09 17:34:32.667010+00:00
[2024-03-12T17:33:18.263+0000] {standard_task_runner.py:60} INFO - Started process 315 to run task
[2024-03-12T17:33:18.292+0000] {standard_task_runner.py:87} INFO - Running: ['***', 'tasks', 'run', 'ETL_Flow', 'fact_stg2dwh', 'manual__2024-03-09T17:34:32.667010+00:00', '--job-id', '472', '--raw', '--subdir', 'DAGS_FOLDER/etl2.py', '--cfg-path', '/tmp/tmpq0drpccl']
[2024-03-12T17:33:18.299+0000] {standard_task_runner.py:88} INFO - Job 472: Subtask fact_stg2dwh
[2024-03-12T17:33:18.838+0000] {task_command.py:423} INFO - Running <TaskInstance: ETL_Flow.fact_stg2dwh manual__2024-03-09T17:34:32.667010+00:00 [running]> on host e2878ba2ad26
[2024-03-12T17:33:19.615+0000] {taskinstance.py:2510} INFO - Exporting env vars: AIRFLOW_CTX_DAG_OWNER='coder2j' AIRFLOW_CTX_DAG_ID='ETL_Flow' AIRFLOW_CTX_TASK_ID='fact_stg2dwh' AIRFLOW_CTX_EXECUTION_DATE='2024-03-09T17:34:32.667010+00:00' AIRFLOW_CTX_TRY_NUMBER='2' AIRFLOW_CTX_DAG_RUN_ID='manual__2024-03-09T17:34:32.667010+00:00'
[2024-03-12T17:33:19.623+0000] {sql.py:276} INFO - Executing: insert into DWH_Fact_Product_In_Order
select * from
STG_Fact_Product_In_Order;
[2024-03-12T17:33:19.668+0000] {base.py:83} INFO - Using connection ID 'postgres_localhost' for task execution.
[2024-03-12T17:33:19.788+0000] {base.py:83} INFO - Using connection ID 'postgres_localhost' for task execution.
[2024-03-12T17:33:20.023+0000] {sql.py:457} INFO - Running statement: insert into DWH_Fact_Product_In_Order
select * from
STG_Fact_Product_In_Order;, parameters: None
[2024-03-12T17:33:20.183+0000] {taskinstance.py:2728} ERROR - Task failed with exception
Traceback (most recent call last):
  File "/home/airflow/.local/lib/python3.8/site-packages/airflow/models/taskinstance.py", line 444, in _execute_task
    result = _execute_callable(context=context, **execute_callable_kwargs)
  File "/home/airflow/.local/lib/python3.8/site-packages/airflow/models/taskinstance.py", line 414, in _execute_callable
    return execute_callable(context=context, **execute_callable_kwargs)
  File "/home/airflow/.local/lib/python3.8/site-packages/airflow/providers/common/sql/operators/sql.py", line 282, in execute
    output = hook.run(
  File "/home/airflow/.local/lib/python3.8/site-packages/airflow/providers/common/sql/hooks/sql.py", line 404, in run
    self._run_command(cur, sql_statement, parameters)
  File "/home/airflow/.local/lib/python3.8/site-packages/airflow/providers/common/sql/hooks/sql.py", line 462, in _run_command
    cur.execute(sql_statement)
psycopg2.errors.UndefinedTable: relation "dwh_fact_product_in_order" does not exist
LINE 1: insert into DWH_Fact_Product_In_Order
                    ^

[2024-03-12T17:33:20.464+0000] {taskinstance.py:1149} INFO - Marking task as UP_FOR_RETRY. dag_id=ETL_Flow, task_id=fact_stg2dwh, execution_date=20240309T173432, start_date=20240312T173318, end_date=20240312T173320
[2024-03-12T17:33:20.658+0000] {standard_task_runner.py:107} ERROR - Failed to execute job 472 for task fact_stg2dwh (relation "dwh_fact_product_in_order" does not exist
LINE 1: insert into DWH_Fact_Product_In_Order
                    ^
; 315)
[2024-03-12T17:33:20.824+0000] {local_task_job_runner.py:234} INFO - Task exited with return code 1
[2024-03-12T17:33:22.225+0000] {taskinstance.py:3309} INFO - 0 downstream tasks scheduled from follow-on schedule check
