[2024-03-12T17:57:07.827+0000] {taskinstance.py:1979} INFO - Dependencies all met for dep_context=non-requeueable deps ti=<TaskInstance: ETL_Flow.insert_data_from_excel scheduled__2024-03-05T06:00:00+00:00 [queued]>
[2024-03-12T17:57:08.021+0000] {taskinstance.py:1979} INFO - Dependencies all met for dep_context=requeueable deps ti=<TaskInstance: ETL_Flow.insert_data_from_excel scheduled__2024-03-05T06:00:00+00:00 [queued]>
[2024-03-12T17:57:08.026+0000] {taskinstance.py:2193} INFO - Starting attempt 1 of 6
[2024-03-12T17:57:08.218+0000] {taskinstance.py:2214} INFO - Executing <Task(PythonOperator): insert_data_from_excel> on 2024-03-05 06:00:00+00:00
[2024-03-12T17:57:08.256+0000] {standard_task_runner.py:60} INFO - Started process 1591 to run task
[2024-03-12T17:57:08.342+0000] {standard_task_runner.py:87} INFO - Running: ['***', 'tasks', 'run', 'ETL_Flow', 'insert_data_from_excel', 'scheduled__2024-03-05T06:00:00+00:00', '--job-id', '856', '--raw', '--subdir', 'DAGS_FOLDER/etl2.py', '--cfg-path', '/tmp/tmpm_tm2e53']
[2024-03-12T17:57:08.397+0000] {standard_task_runner.py:88} INFO - Job 856: Subtask insert_data_from_excel
[2024-03-12T17:57:09.080+0000] {task_command.py:423} INFO - Running <TaskInstance: ETL_Flow.insert_data_from_excel scheduled__2024-03-05T06:00:00+00:00 [running]> on host e2878ba2ad26
[2024-03-12T17:57:12.803+0000] {taskinstance.py:2510} INFO - Exporting env vars: AIRFLOW_CTX_DAG_OWNER='coder2j' AIRFLOW_CTX_DAG_ID='ETL_Flow' AIRFLOW_CTX_TASK_ID='insert_data_from_excel' AIRFLOW_CTX_EXECUTION_DATE='2024-03-05T06:00:00+00:00' AIRFLOW_CTX_TRY_NUMBER='1' AIRFLOW_CTX_DAG_RUN_ID='scheduled__2024-03-05T06:00:00+00:00'
[2024-03-12T17:57:12.856+0000] {taskinstance.py:2728} ERROR - Task failed with exception
Traceback (most recent call last):
  File "/home/airflow/.local/lib/python3.8/site-packages/airflow/models/taskinstance.py", line 444, in _execute_task
    result = _execute_callable(context=context, **execute_callable_kwargs)
  File "/home/airflow/.local/lib/python3.8/site-packages/airflow/models/taskinstance.py", line 414, in _execute_callable
    return execute_callable(context=context, **execute_callable_kwargs)
  File "/home/airflow/.local/lib/python3.8/site-packages/airflow/operators/python.py", line 200, in execute
    return_value = self.execute_callable()
  File "/home/airflow/.local/lib/python3.8/site-packages/airflow/operators/python.py", line 217, in execute_callable
    return self.python_callable(*self.op_args, **self.op_kwargs)
  File "/opt/airflow/dags/etl2.py", line 25, in insert_data_from_excel
    df = pd.read_excel(file_path)
  File "/home/airflow/.local/lib/python3.8/site-packages/pandas/io/excel/_base.py", line 478, in read_excel
    io = ExcelFile(io, storage_options=storage_options, engine=engine)
  File "/home/airflow/.local/lib/python3.8/site-packages/pandas/io/excel/_base.py", line 1496, in __init__
    ext = inspect_excel_format(
  File "/home/airflow/.local/lib/python3.8/site-packages/pandas/io/excel/_base.py", line 1371, in inspect_excel_format
    with get_handle(
  File "/home/airflow/.local/lib/python3.8/site-packages/pandas/io/common.py", line 868, in get_handle
    handle = open(handle, ioargs.mode)
FileNotFoundError: [Errno 2] No such file or directory: 'C:\\Users\\Gstat\\Downloads\\customers.xlsx'
[2024-03-12T17:57:13.065+0000] {taskinstance.py:1149} INFO - Marking task as UP_FOR_RETRY. dag_id=ETL_Flow, task_id=insert_data_from_excel, execution_date=20240305T060000, start_date=20240312T175707, end_date=20240312T175713
[2024-03-12T17:57:13.380+0000] {standard_task_runner.py:107} ERROR - Failed to execute job 856 for task insert_data_from_excel ([Errno 2] No such file or directory: 'C:\\Users\\Gstat\\Downloads\\customers.xlsx'; 1591)
[2024-03-12T17:57:13.588+0000] {local_task_job_runner.py:234} INFO - Task exited with return code 1
[2024-03-12T17:57:13.683+0000] {taskinstance.py:3309} INFO - 0 downstream tasks scheduled from follow-on schedule check
