[2024-03-16T10:55:25.656+0000] {taskinstance.py:1979} INFO - Dependencies all met for dep_context=non-requeueable deps ti=<TaskInstance: ETL_Flow.insert_data_from_files manual__2024-03-16T10:15:18.109594+00:00 [queued]>
[2024-03-16T10:55:25.667+0000] {taskinstance.py:1979} INFO - Dependencies all met for dep_context=requeueable deps ti=<TaskInstance: ETL_Flow.insert_data_from_files manual__2024-03-16T10:15:18.109594+00:00 [queued]>
[2024-03-16T10:55:25.668+0000] {taskinstance.py:2193} INFO - Starting attempt 3 of 8
[2024-03-16T10:55:25.687+0000] {taskinstance.py:2214} INFO - Executing <Task(PythonOperator): insert_data_from_files> on 2024-03-16 10:15:18.109594+00:00
[2024-03-16T10:55:25.695+0000] {standard_task_runner.py:60} INFO - Started process 2125 to run task
[2024-03-16T10:55:25.699+0000] {standard_task_runner.py:87} INFO - Running: ['***', 'tasks', 'run', 'ETL_Flow', 'insert_data_from_files', 'manual__2024-03-16T10:15:18.109594+00:00', '--job-id', '1765', '--raw', '--subdir', 'DAGS_FOLDER/etl2.py', '--cfg-path', '/tmp/tmp_lfijvbs']
[2024-03-16T10:55:25.702+0000] {standard_task_runner.py:88} INFO - Job 1765: Subtask insert_data_from_files
[2024-03-16T10:55:25.762+0000] {task_command.py:423} INFO - Running <TaskInstance: ETL_Flow.insert_data_from_files manual__2024-03-16T10:15:18.109594+00:00 [running]> on host 3f630fdac388
[2024-03-16T10:55:26.092+0000] {taskinstance.py:2510} INFO - Exporting env vars: AIRFLOW_CTX_DAG_OWNER='coder2j' AIRFLOW_CTX_DAG_ID='ETL_Flow' AIRFLOW_CTX_TASK_ID='insert_data_from_files' AIRFLOW_CTX_EXECUTION_DATE='2024-03-16T10:15:18.109594+00:00' AIRFLOW_CTX_TRY_NUMBER='3' AIRFLOW_CTX_DAG_RUN_ID='manual__2024-03-16T10:15:18.109594+00:00'
[2024-03-16T10:55:26.097+0000] {taskinstance.py:2728} ERROR - Task failed with exception
Traceback (most recent call last):
  File "/home/airflow/.local/lib/python3.8/site-packages/airflow/models/taskinstance.py", line 444, in _execute_task
    result = _execute_callable(context=context, **execute_callable_kwargs)
  File "/home/airflow/.local/lib/python3.8/site-packages/airflow/models/taskinstance.py", line 414, in _execute_callable
    return execute_callable(context=context, **execute_callable_kwargs)
  File "/home/airflow/.local/lib/python3.8/site-packages/airflow/operators/python.py", line 200, in execute
    return_value = self.execute_callable()
  File "/home/airflow/.local/lib/python3.8/site-packages/airflow/operators/python.py", line 217, in execute_callable
    return self.python_callable(*self.op_args, **self.op_kwargs)
  File "/opt/airflow/dags/etl2.py", line 76, in read_csv_and_insert
    df = pd.read_excel('operationaldata/orders.xlsx')
  File "/home/airflow/.local/lib/python3.8/site-packages/pandas/io/excel/_base.py", line 478, in read_excel
    io = ExcelFile(io, storage_options=storage_options, engine=engine)
  File "/home/airflow/.local/lib/python3.8/site-packages/pandas/io/excel/_base.py", line 1496, in __init__
    ext = inspect_excel_format(
  File "/home/airflow/.local/lib/python3.8/site-packages/pandas/io/excel/_base.py", line 1371, in inspect_excel_format
    with get_handle(
  File "/home/airflow/.local/lib/python3.8/site-packages/pandas/io/common.py", line 868, in get_handle
    handle = open(handle, ioargs.mode)
FileNotFoundError: [Errno 2] No such file or directory: 'operationaldata/orders.xlsx'
[2024-03-16T10:55:26.116+0000] {taskinstance.py:1149} INFO - Marking task as UP_FOR_RETRY. dag_id=ETL_Flow, task_id=insert_data_from_files, execution_date=20240316T101518, start_date=20240316T105525, end_date=20240316T105526
[2024-03-16T10:55:26.131+0000] {standard_task_runner.py:107} ERROR - Failed to execute job 1765 for task insert_data_from_files ([Errno 2] No such file or directory: 'operationaldata/orders.xlsx'; 2125)
[2024-03-16T10:55:26.154+0000] {local_task_job_runner.py:234} INFO - Task exited with return code 1
[2024-03-16T10:55:26.186+0000] {taskinstance.py:3309} INFO - 0 downstream tasks scheduled from follow-on schedule check
