[2024-03-12T18:11:30.397+0000] {taskinstance.py:1979} INFO - Dependencies all met for dep_context=non-requeueable deps ti=<TaskInstance: ETL_Flow.referential_integrity manual__2024-03-12T18:05:45.652427+00:00 [queued]>
[2024-03-12T18:11:30.497+0000] {taskinstance.py:1979} INFO - Dependencies all met for dep_context=requeueable deps ti=<TaskInstance: ETL_Flow.referential_integrity manual__2024-03-12T18:05:45.652427+00:00 [queued]>
[2024-03-12T18:11:30.500+0000] {taskinstance.py:2193} INFO - Starting attempt 2 of 6
[2024-03-12T18:11:30.576+0000] {taskinstance.py:2214} INFO - Executing <Task(PostgresOperator): referential_integrity> on 2024-03-12 18:05:45.652427+00:00
[2024-03-12T18:11:30.601+0000] {standard_task_runner.py:60} INFO - Started process 313 to run task
[2024-03-12T18:11:30.641+0000] {standard_task_runner.py:87} INFO - Running: ['***', 'tasks', 'run', 'ETL_Flow', 'referential_integrity', 'manual__2024-03-12T18:05:45.652427+00:00', '--job-id', '949', '--raw', '--subdir', 'DAGS_FOLDER/etl2.py', '--cfg-path', '/tmp/tmppoyfgdti']
[2024-03-12T18:11:30.658+0000] {standard_task_runner.py:88} INFO - Job 949: Subtask referential_integrity
[2024-03-12T18:11:31.019+0000] {task_command.py:423} INFO - Running <TaskInstance: ETL_Flow.referential_integrity manual__2024-03-12T18:05:45.652427+00:00 [running]> on host 89a69a757939
[2024-03-12T18:11:32.693+0000] {taskinstance.py:2510} INFO - Exporting env vars: AIRFLOW_CTX_DAG_OWNER='coder2j' AIRFLOW_CTX_DAG_ID='ETL_Flow' AIRFLOW_CTX_TASK_ID='referential_integrity' AIRFLOW_CTX_EXECUTION_DATE='2024-03-12T18:05:45.652427+00:00' AIRFLOW_CTX_TRY_NUMBER='2' AIRFLOW_CTX_DAG_RUN_ID='manual__2024-03-12T18:05:45.652427+00:00'
[2024-03-12T18:11:32.710+0000] {sql.py:276} INFO - Executing: update STG_Fact_Product_In_Order
set Product_ID='unknown'
where Product_ID not in (
                            select distinct Product_ID 
                            from DWH_Dim_Products
                        );

update STG_Dim_Employees
set Employee_ID='unknown'
where Employee_ID not in (
                            select distinct Employee_ID 
                            from DWH_Dim_Employees
                        );

update STG_Dim_Customers
set Customer_ID='unknown'
where Customer_ID not in (
                            select distinct Customer_ID 
                            from DWH_Dim_Customers
                        );

[2024-03-12T18:11:32.768+0000] {base.py:83} INFO - Using connection ID 'postgres_localhost' for task execution.
[2024-03-12T18:11:32.850+0000] {base.py:83} INFO - Using connection ID 'postgres_localhost' for task execution.
[2024-03-12T18:11:32.916+0000] {sql.py:457} INFO - Running statement: update STG_Fact_Product_In_Order
set Product_ID='unknown'
where Product_ID not in (
                            select distinct Product_ID 
                            from DWH_Dim_Products
                        );

update STG_Dim_Employees
set Employee_ID='unknown'
where Employee_ID not in (
                            select distinct Employee_ID 
                            from DWH_Dim_Employees
                        );

update STG_Dim_Customers
set Customer_ID='unknown'
where Customer_ID not in (
                            select distinct Customer_ID 
                            from DWH_Dim_Customers
                        );
, parameters: None
[2024-03-12T18:11:33.015+0000] {taskinstance.py:2728} ERROR - Task failed with exception
Traceback (most recent call last):
  File "/home/airflow/.local/lib/python3.8/site-packages/airflow/models/taskinstance.py", line 444, in _execute_task
    result = _execute_callable(context=context, **execute_callable_kwargs)
  File "/home/airflow/.local/lib/python3.8/site-packages/airflow/models/taskinstance.py", line 414, in _execute_callable
    return execute_callable(context=context, **execute_callable_kwargs)
  File "/home/airflow/.local/lib/python3.8/site-packages/airflow/providers/common/sql/operators/sql.py", line 282, in execute
    output = hook.run(
  File "/home/airflow/.local/lib/python3.8/site-packages/airflow/providers/common/sql/hooks/sql.py", line 404, in run
    self._run_command(cur, sql_statement, parameters)
  File "/home/airflow/.local/lib/python3.8/site-packages/airflow/providers/common/sql/hooks/sql.py", line 462, in _run_command
    cur.execute(sql_statement)
psycopg2.errors.UndefinedTable: relation "stg_fact_product_in_order" does not exist
LINE 1: update STG_Fact_Product_In_Order
               ^

[2024-03-12T18:11:33.229+0000] {taskinstance.py:1149} INFO - Marking task as UP_FOR_RETRY. dag_id=ETL_Flow, task_id=referential_integrity, execution_date=20240312T180545, start_date=20240312T181130, end_date=20240312T181133
[2024-03-12T18:11:33.493+0000] {standard_task_runner.py:107} ERROR - Failed to execute job 949 for task referential_integrity (relation "stg_fact_product_in_order" does not exist
LINE 1: update STG_Fact_Product_In_Order
               ^
; 313)
[2024-03-12T18:11:33.648+0000] {local_task_job_runner.py:234} INFO - Task exited with return code 1
[2024-03-12T18:11:33.735+0000] {taskinstance.py:3309} INFO - 0 downstream tasks scheduled from follow-on schedule check
