[2024-03-12T18:09:42.083+0000] {taskinstance.py:1979} INFO - Dependencies all met for dep_context=non-requeueable deps ti=<TaskInstance: ETL_Flow.truncate_mrr_stg manual__2024-03-12T18:09:34.801045+00:00 [queued]>
[2024-03-12T18:09:42.157+0000] {taskinstance.py:1979} INFO - Dependencies all met for dep_context=requeueable deps ti=<TaskInstance: ETL_Flow.truncate_mrr_stg manual__2024-03-12T18:09:34.801045+00:00 [queued]>
[2024-03-12T18:09:42.160+0000] {taskinstance.py:2193} INFO - Starting attempt 1 of 6
[2024-03-12T18:09:42.435+0000] {taskinstance.py:2214} INFO - Executing <Task(PostgresOperator): truncate_mrr_stg> on 2024-03-12 18:09:34.801045+00:00
[2024-03-12T18:09:42.530+0000] {standard_task_runner.py:60} INFO - Started process 260 to run task
[2024-03-12T18:09:42.621+0000] {standard_task_runner.py:87} INFO - Running: ['***', 'tasks', 'run', 'ETL_Flow', 'truncate_mrr_stg', 'manual__2024-03-12T18:09:34.801045+00:00', '--job-id', '937', '--raw', '--subdir', 'DAGS_FOLDER/etl2.py', '--cfg-path', '/tmp/tmpw8ivo5d2']
[2024-03-12T18:09:42.713+0000] {standard_task_runner.py:88} INFO - Job 937: Subtask truncate_mrr_stg
[2024-03-12T18:09:44.657+0000] {task_command.py:423} INFO - Running <TaskInstance: ETL_Flow.truncate_mrr_stg manual__2024-03-12T18:09:34.801045+00:00 [running]> on host 89a69a757939
[2024-03-12T18:09:58.958+0000] {job.py:213} ERROR - Job heartbeat got an exception
Traceback (most recent call last):
  File "/home/airflow/.local/lib/python3.8/site-packages/sqlalchemy/engine/base.py", line 3371, in _wrap_pool_connect
    return fn()
  File "/home/airflow/.local/lib/python3.8/site-packages/sqlalchemy/pool/base.py", line 327, in connect
    return _ConnectionFairy._checkout(self)
  File "/home/airflow/.local/lib/python3.8/site-packages/sqlalchemy/pool/base.py", line 894, in _checkout
    fairy = _ConnectionRecord.checkout(pool)
  File "/home/airflow/.local/lib/python3.8/site-packages/sqlalchemy/pool/base.py", line 493, in checkout
    rec = pool._do_get()
  File "/home/airflow/.local/lib/python3.8/site-packages/sqlalchemy/pool/impl.py", line 256, in _do_get
    return self._create_connection()
  File "/home/airflow/.local/lib/python3.8/site-packages/sqlalchemy/pool/base.py", line 273, in _create_connection
    return _ConnectionRecord(self)
  File "/home/airflow/.local/lib/python3.8/site-packages/sqlalchemy/pool/base.py", line 388, in __init__
    self.__connect()
  File "/home/airflow/.local/lib/python3.8/site-packages/sqlalchemy/pool/base.py", line 691, in __connect
    pool.logger.debug("Error on connect(): %s", e)
  File "/home/airflow/.local/lib/python3.8/site-packages/sqlalchemy/util/langhelpers.py", line 70, in __exit__
    compat.raise_(
  File "/home/airflow/.local/lib/python3.8/site-packages/sqlalchemy/util/compat.py", line 211, in raise_
    raise exception
  File "/home/airflow/.local/lib/python3.8/site-packages/sqlalchemy/pool/base.py", line 686, in __connect
    self.dbapi_connection = connection = pool._invoke_creator(self)
  File "/home/airflow/.local/lib/python3.8/site-packages/sqlalchemy/engine/create.py", line 574, in connect
    return dialect.connect(*cargs, **cparams)
  File "/home/airflow/.local/lib/python3.8/site-packages/sqlalchemy/engine/default.py", line 598, in connect
    return self.dbapi.connect(*cargs, **cparams)
  File "/home/airflow/.local/lib/python3.8/site-packages/psycopg2/__init__.py", line 122, in connect
    conn = _connect(dsn, connection_factory=connection_factory, **kwasync)
psycopg2.OperationalError: could not translate host name "postgres" to address: Temporary failure in name resolution


The above exception was the direct cause of the following exception:

Traceback (most recent call last):
  File "/home/airflow/.local/lib/python3.8/site-packages/airflow/jobs/job.py", line 187, in heartbeat
    self._merge_from(Job._fetch_from_db(self, session))
  File "/home/airflow/.local/lib/python3.8/site-packages/airflow/api_internal/internal_api_call.py", line 114, in wrapper
    return func(*args, **kwargs)
  File "/home/airflow/.local/lib/python3.8/site-packages/airflow/utils/session.py", line 76, in wrapper
    return func(*args, **kwargs)
  File "/home/airflow/.local/lib/python3.8/site-packages/airflow/jobs/job.py", line 308, in _fetch_from_db
    session.merge(job)
  File "/home/airflow/.local/lib/python3.8/site-packages/sqlalchemy/orm/session.py", line 3056, in merge
    return self._merge(
  File "/home/airflow/.local/lib/python3.8/site-packages/sqlalchemy/orm/session.py", line 3136, in _merge
    merged = self.get(
  File "/home/airflow/.local/lib/python3.8/site-packages/sqlalchemy/orm/session.py", line 2853, in get
    return self._get_impl(
  File "/home/airflow/.local/lib/python3.8/site-packages/sqlalchemy/orm/session.py", line 2975, in _get_impl
    return db_load_fn(
  File "/home/airflow/.local/lib/python3.8/site-packages/sqlalchemy/orm/loading.py", line 530, in load_on_pk_identity
    session.execute(
  File "/home/airflow/.local/lib/python3.8/site-packages/sqlalchemy/orm/session.py", line 1716, in execute
    conn = self._connection_for_bind(bind)
  File "/home/airflow/.local/lib/python3.8/site-packages/sqlalchemy/orm/session.py", line 1555, in _connection_for_bind
    return self._transaction._connection_for_bind(
  File "/home/airflow/.local/lib/python3.8/site-packages/sqlalchemy/orm/session.py", line 750, in _connection_for_bind
    conn = bind.connect()
  File "/home/airflow/.local/lib/python3.8/site-packages/sqlalchemy/future/engine.py", line 412, in connect
    return super(Engine, self).connect()
  File "/home/airflow/.local/lib/python3.8/site-packages/sqlalchemy/engine/base.py", line 3325, in connect
    return self._connection_cls(self, close_with_result=close_with_result)
  File "/home/airflow/.local/lib/python3.8/site-packages/sqlalchemy/engine/base.py", line 96, in __init__
    else engine.raw_connection()
  File "/home/airflow/.local/lib/python3.8/site-packages/sqlalchemy/engine/base.py", line 3404, in raw_connection
    return self._wrap_pool_connect(self.pool.connect, _connection)
  File "/home/airflow/.local/lib/python3.8/site-packages/sqlalchemy/engine/base.py", line 3374, in _wrap_pool_connect
    Connection._handle_dbapi_exception_noconnection(
  File "/home/airflow/.local/lib/python3.8/site-packages/sqlalchemy/engine/base.py", line 2208, in _handle_dbapi_exception_noconnection
    util.raise_(
  File "/home/airflow/.local/lib/python3.8/site-packages/sqlalchemy/util/compat.py", line 211, in raise_
    raise exception
  File "/home/airflow/.local/lib/python3.8/site-packages/sqlalchemy/engine/base.py", line 3371, in _wrap_pool_connect
    return fn()
  File "/home/airflow/.local/lib/python3.8/site-packages/sqlalchemy/pool/base.py", line 327, in connect
    return _ConnectionFairy._checkout(self)
  File "/home/airflow/.local/lib/python3.8/site-packages/sqlalchemy/pool/base.py", line 894, in _checkout
    fairy = _ConnectionRecord.checkout(pool)
  File "/home/airflow/.local/lib/python3.8/site-packages/sqlalchemy/pool/base.py", line 493, in checkout
    rec = pool._do_get()
  File "/home/airflow/.local/lib/python3.8/site-packages/sqlalchemy/pool/impl.py", line 256, in _do_get
    return self._create_connection()
  File "/home/airflow/.local/lib/python3.8/site-packages/sqlalchemy/pool/base.py", line 273, in _create_connection
    return _ConnectionRecord(self)
  File "/home/airflow/.local/lib/python3.8/site-packages/sqlalchemy/pool/base.py", line 388, in __init__
    self.__connect()
  File "/home/airflow/.local/lib/python3.8/site-packages/sqlalchemy/pool/base.py", line 691, in __connect
    pool.logger.debug("Error on connect(): %s", e)
  File "/home/airflow/.local/lib/python3.8/site-packages/sqlalchemy/util/langhelpers.py", line 70, in __exit__
    compat.raise_(
  File "/home/airflow/.local/lib/python3.8/site-packages/sqlalchemy/util/compat.py", line 211, in raise_
    raise exception
  File "/home/airflow/.local/lib/python3.8/site-packages/sqlalchemy/pool/base.py", line 686, in __connect
    self.dbapi_connection = connection = pool._invoke_creator(self)
  File "/home/airflow/.local/lib/python3.8/site-packages/sqlalchemy/engine/create.py", line 574, in connect
    return dialect.connect(*cargs, **cparams)
  File "/home/airflow/.local/lib/python3.8/site-packages/sqlalchemy/engine/default.py", line 598, in connect
    return self.dbapi.connect(*cargs, **cparams)
  File "/home/airflow/.local/lib/python3.8/site-packages/psycopg2/__init__.py", line 122, in connect
    conn = _connect(dsn, connection_factory=connection_factory, **kwasync)
sqlalchemy.exc.OperationalError: (psycopg2.OperationalError) could not translate host name "postgres" to address: Temporary failure in name resolution

(Background on this error at: https://sqlalche.me/e/14/e3q8)
[2024-03-12T18:09:59.357+0000] {job.py:221} ERROR - Job heartbeat failed with error. Scheduler is in unhealthy state
[2024-03-12T18:10:02.081+0000] {taskinstance.py:2510} INFO - Exporting env vars: AIRFLOW_CTX_DAG_OWNER='coder2j' AIRFLOW_CTX_DAG_ID='ETL_Flow' AIRFLOW_CTX_TASK_ID='truncate_mrr_stg' AIRFLOW_CTX_EXECUTION_DATE='2024-03-12T18:09:34.801045+00:00' AIRFLOW_CTX_TRY_NUMBER='1' AIRFLOW_CTX_DAG_RUN_ID='manual__2024-03-12T18:09:34.801045+00:00'
[2024-03-12T18:10:02.109+0000] {sql.py:276} INFO - Executing: TRUNCATE TABLE MRR_Dim_Customers;
TRUNCATE TABLE MRR_Dim_Employees;
TRUNCATE TABLE MRR_Dim_Products;
TRUNCATE TABLE MRR_Fact_Details;
TRUNCATE TABLE MRR_Fact_Orders;
TRUNCATE TABLE STG_Dim_Customers;
TRUNCATE TABLE STG_Dim_Dates;
TRUNCATE TABLE STG_Dim_Employees;
TRUNCATE TABLE STG_Dim_Products;
TRUNCATE TABLE STG_Dim_Time;
TRUNCATE TABLE STG_Fact_Product_In_Order;
TRUNCATE TABLE STG_Fact_Product_In_Order;
TRUNCATE TABLE STG_Snapshot_Customers_Transactions;
[2024-03-12T18:10:02.235+0000] {base.py:83} INFO - Using connection ID 'postgres_localhost' for task execution.
[2024-03-12T18:10:02.346+0000] {base.py:83} INFO - Using connection ID 'postgres_localhost' for task execution.
[2024-03-12T18:10:02.721+0000] {sql.py:457} INFO - Running statement: TRUNCATE TABLE MRR_Dim_Customers;
TRUNCATE TABLE MRR_Dim_Employees;
TRUNCATE TABLE MRR_Dim_Products;
TRUNCATE TABLE MRR_Fact_Details;
TRUNCATE TABLE MRR_Fact_Orders;
TRUNCATE TABLE STG_Dim_Customers;
TRUNCATE TABLE STG_Dim_Dates;
TRUNCATE TABLE STG_Dim_Employees;
TRUNCATE TABLE STG_Dim_Products;
TRUNCATE TABLE STG_Dim_Time;
TRUNCATE TABLE STG_Fact_Product_In_Order;
TRUNCATE TABLE STG_Fact_Product_In_Order;
TRUNCATE TABLE STG_Snapshot_Customers_Transactions;, parameters: None
[2024-03-12T18:10:02.742+0000] {taskinstance.py:2728} ERROR - Task failed with exception
Traceback (most recent call last):
  File "/home/airflow/.local/lib/python3.8/site-packages/airflow/models/taskinstance.py", line 444, in _execute_task
    result = _execute_callable(context=context, **execute_callable_kwargs)
  File "/home/airflow/.local/lib/python3.8/site-packages/airflow/models/taskinstance.py", line 414, in _execute_callable
    return execute_callable(context=context, **execute_callable_kwargs)
  File "/home/airflow/.local/lib/python3.8/site-packages/airflow/providers/common/sql/operators/sql.py", line 282, in execute
    output = hook.run(
  File "/home/airflow/.local/lib/python3.8/site-packages/airflow/providers/common/sql/hooks/sql.py", line 404, in run
    self._run_command(cur, sql_statement, parameters)
  File "/home/airflow/.local/lib/python3.8/site-packages/airflow/providers/common/sql/hooks/sql.py", line 462, in _run_command
    cur.execute(sql_statement)
psycopg2.errors.UndefinedTable: relation "mrr_dim_customers" does not exist

[2024-03-12T18:10:02.900+0000] {taskinstance.py:1149} INFO - Marking task as UP_FOR_RETRY. dag_id=ETL_Flow, task_id=truncate_mrr_stg, execution_date=20240312T180934, start_date=20240312T180942, end_date=20240312T181002
[2024-03-12T18:10:03.090+0000] {standard_task_runner.py:107} ERROR - Failed to execute job 937 for task truncate_mrr_stg (relation "mrr_dim_customers" does not exist
; 260)
[2024-03-12T18:10:03.220+0000] {local_task_job_runner.py:234} INFO - Task exited with return code 1
[2024-03-12T18:10:03.476+0000] {taskinstance.py:3309} INFO - 0 downstream tasks scheduled from follow-on schedule check
