[2024-03-20T12:20:46.024+0000] {taskinstance.py:1979} INFO - Dependencies all met for dep_context=non-requeueable deps ti=<TaskInstance: ETL_Flow.insert_data_from_files manual__2024-03-20T11:16:27.525070+00:00 [queued]>
[2024-03-20T12:20:46.040+0000] {taskinstance.py:1979} INFO - Dependencies all met for dep_context=requeueable deps ti=<TaskInstance: ETL_Flow.insert_data_from_files manual__2024-03-20T11:16:27.525070+00:00 [queued]>
[2024-03-20T12:20:46.042+0000] {taskinstance.py:2193} INFO - Starting attempt 19 of 20
[2024-03-20T12:20:46.076+0000] {taskinstance.py:2214} INFO - Executing <Task(PythonOperator): insert_data_from_files> on 2024-03-20 11:16:27.525070+00:00
[2024-03-20T12:20:46.085+0000] {standard_task_runner.py:60} INFO - Started process 1112 to run task
[2024-03-20T12:20:46.094+0000] {standard_task_runner.py:87} INFO - Running: ['***', 'tasks', 'run', 'ETL_Flow', 'insert_data_from_files', 'manual__2024-03-20T11:16:27.525070+00:00', '--job-id', '2015', '--raw', '--subdir', 'DAGS_FOLDER/etl2.py', '--cfg-path', '/tmp/tmp6oxgeiez']
[2024-03-20T12:20:46.101+0000] {standard_task_runner.py:88} INFO - Job 2015: Subtask insert_data_from_files
[2024-03-20T12:20:46.214+0000] {task_command.py:423} INFO - Running <TaskInstance: ETL_Flow.insert_data_from_files manual__2024-03-20T11:16:27.525070+00:00 [running]> on host a1a2ab3031a9
[2024-03-20T12:20:46.398+0000] {taskinstance.py:2510} INFO - Exporting env vars: AIRFLOW_CTX_DAG_OWNER='coder2j' AIRFLOW_CTX_DAG_ID='ETL_Flow' AIRFLOW_CTX_TASK_ID='insert_data_from_files' AIRFLOW_CTX_EXECUTION_DATE='2024-03-20T11:16:27.525070+00:00' AIRFLOW_CTX_TRY_NUMBER='19' AIRFLOW_CTX_DAG_RUN_ID='manual__2024-03-20T11:16:27.525070+00:00'
[2024-03-20T12:20:46.402+0000] {taskinstance.py:2728} ERROR - Task failed with exception
Traceback (most recent call last):
  File "/home/airflow/.local/lib/python3.8/site-packages/airflow/models/taskinstance.py", line 444, in _execute_task
    result = _execute_callable(context=context, **execute_callable_kwargs)
  File "/home/airflow/.local/lib/python3.8/site-packages/airflow/models/taskinstance.py", line 414, in _execute_callable
    return execute_callable(context=context, **execute_callable_kwargs)
  File "/home/airflow/.local/lib/python3.8/site-packages/airflow/operators/python.py", line 200, in execute
    return_value = self.execute_callable()
  File "/home/airflow/.local/lib/python3.8/site-packages/airflow/operators/python.py", line 217, in execute_callable
    return self.python_callable(*self.op_args, **self.op_kwargs)
  File "/opt/airflow/dags/etl2.py", line 39, in read_excel_and_insert
    book= load_workbook('data.xlsx')
  File "/home/airflow/.local/lib/python3.8/site-packages/openpyxl/reader/excel.py", line 344, in load_workbook
    reader = ExcelReader(filename, read_only, keep_vba,
  File "/home/airflow/.local/lib/python3.8/site-packages/openpyxl/reader/excel.py", line 123, in __init__
    self.archive = _validate_archive(fn)
  File "/home/airflow/.local/lib/python3.8/site-packages/openpyxl/reader/excel.py", line 95, in _validate_archive
    archive = ZipFile(filename, 'r')
  File "/usr/local/lib/python3.8/zipfile.py", line 1251, in __init__
    self.fp = io.open(file, filemode)
FileNotFoundError: [Errno 2] No such file or directory: 'data.xlsx'
[2024-03-20T12:20:46.438+0000] {taskinstance.py:1149} INFO - Marking task as UP_FOR_RETRY. dag_id=ETL_Flow, task_id=insert_data_from_files, execution_date=20240320T111627, start_date=20240320T122046, end_date=20240320T122046
[2024-03-20T12:20:46.466+0000] {standard_task_runner.py:107} ERROR - Failed to execute job 2015 for task insert_data_from_files ([Errno 2] No such file or directory: 'data.xlsx'; 1112)
[2024-03-20T12:20:46.508+0000] {local_task_job_runner.py:234} INFO - Task exited with return code 1
[2024-03-20T12:20:46.561+0000] {taskinstance.py:3309} INFO - 0 downstream tasks scheduled from follow-on schedule check
