[2024-03-12T17:31:58.727+0000] {taskinstance.py:1979} INFO - Dependencies all met for dep_context=non-requeueable deps ti=<TaskInstance: ETL_Flow.referential_integrity scheduled__2024-03-02T06:00:00+00:00 [queued]>
[2024-03-12T17:31:58.774+0000] {taskinstance.py:1979} INFO - Dependencies all met for dep_context=requeueable deps ti=<TaskInstance: ETL_Flow.referential_integrity scheduled__2024-03-02T06:00:00+00:00 [queued]>
[2024-03-12T17:31:58.799+0000] {taskinstance.py:2193} INFO - Starting attempt 3 of 6
[2024-03-12T17:31:59.036+0000] {taskinstance.py:2214} INFO - Executing <Task(PostgresOperator): referential_integrity> on 2024-03-02 06:00:00+00:00
[2024-03-12T17:31:59.068+0000] {standard_task_runner.py:60} INFO - Started process 121 to run task
[2024-03-12T17:31:59.265+0000] {standard_task_runner.py:87} INFO - Running: ['***', 'tasks', 'run', 'ETL_Flow', 'referential_integrity', 'scheduled__2024-03-02T06:00:00+00:00', '--job-id', '382', '--raw', '--subdir', 'DAGS_FOLDER/etl2.py', '--cfg-path', '/tmp/tmp2y071pbl']
[2024-03-12T17:31:59.276+0000] {standard_task_runner.py:88} INFO - Job 382: Subtask referential_integrity
[2024-03-12T17:32:00.055+0000] {task_command.py:423} INFO - Running <TaskInstance: ETL_Flow.referential_integrity scheduled__2024-03-02T06:00:00+00:00 [running]> on host e2878ba2ad26
[2024-03-12T17:32:00.476+0000] {taskinstance.py:2510} INFO - Exporting env vars: AIRFLOW_CTX_DAG_OWNER='coder2j' AIRFLOW_CTX_DAG_ID='ETL_Flow' AIRFLOW_CTX_TASK_ID='referential_integrity' AIRFLOW_CTX_EXECUTION_DATE='2024-03-02T06:00:00+00:00' AIRFLOW_CTX_TRY_NUMBER='3' AIRFLOW_CTX_DAG_RUN_ID='scheduled__2024-03-02T06:00:00+00:00'
[2024-03-12T17:32:00.479+0000] {sql.py:276} INFO - Executing: update STG_Fact_Product_In_Order
set Product_ID='unknown'
where Product_ID not in (
                            select distinct Product_ID 
                            from DWH_Dim_Products
                        );

update STG_Dim_Employees
set Employee_ID='unknown'
where Employee_ID not in (
                            select distinct Employee_ID 
                            from DWH_Dim_Employees
                        );

update STG_Dim_Customers
set Customer_ID='unknown'
where Customer_ID not in (
                            select distinct Customer_ID 
                            from DWH_Dim_Customers
                        );

[2024-03-12T17:32:00.513+0000] {base.py:83} INFO - Using connection ID 'postgres_localhost' for task execution.
[2024-03-12T17:32:00.603+0000] {base.py:83} INFO - Using connection ID 'postgres_localhost' for task execution.
[2024-03-12T17:32:00.735+0000] {sql.py:457} INFO - Running statement: update STG_Fact_Product_In_Order
set Product_ID='unknown'
where Product_ID not in (
                            select distinct Product_ID 
                            from DWH_Dim_Products
                        );

update STG_Dim_Employees
set Employee_ID='unknown'
where Employee_ID not in (
                            select distinct Employee_ID 
                            from DWH_Dim_Employees
                        );

update STG_Dim_Customers
set Customer_ID='unknown'
where Customer_ID not in (
                            select distinct Customer_ID 
                            from DWH_Dim_Customers
                        );
, parameters: None
[2024-03-12T17:32:00.815+0000] {taskinstance.py:2728} ERROR - Task failed with exception
Traceback (most recent call last):
  File "/home/airflow/.local/lib/python3.8/site-packages/airflow/models/taskinstance.py", line 444, in _execute_task
    result = _execute_callable(context=context, **execute_callable_kwargs)
  File "/home/airflow/.local/lib/python3.8/site-packages/airflow/models/taskinstance.py", line 414, in _execute_callable
    return execute_callable(context=context, **execute_callable_kwargs)
  File "/home/airflow/.local/lib/python3.8/site-packages/airflow/providers/common/sql/operators/sql.py", line 282, in execute
    output = hook.run(
  File "/home/airflow/.local/lib/python3.8/site-packages/airflow/providers/common/sql/hooks/sql.py", line 404, in run
    self._run_command(cur, sql_statement, parameters)
  File "/home/airflow/.local/lib/python3.8/site-packages/airflow/providers/common/sql/hooks/sql.py", line 462, in _run_command
    cur.execute(sql_statement)
psycopg2.errors.UndefinedTable: relation "stg_fact_product_in_order" does not exist
LINE 1: update STG_Fact_Product_In_Order
               ^

[2024-03-12T17:32:00.906+0000] {taskinstance.py:1149} INFO - Marking task as UP_FOR_RETRY. dag_id=ETL_Flow, task_id=referential_integrity, execution_date=20240302T060000, start_date=20240312T173158, end_date=20240312T173200
[2024-03-12T17:32:01.034+0000] {standard_task_runner.py:107} ERROR - Failed to execute job 382 for task referential_integrity (relation "stg_fact_product_in_order" does not exist
LINE 1: update STG_Fact_Product_In_Order
               ^
; 121)
[2024-03-12T17:32:01.109+0000] {local_task_job_runner.py:234} INFO - Task exited with return code 1
[2024-03-12T17:32:01.239+0000] {taskinstance.py:3309} INFO - 0 downstream tasks scheduled from follow-on schedule check
